No exception raised in try block
in finally block
Test Completed
